Workbook

Sheet Visit Tracker
A1: Region | B1: Area | C1: District | D1: Showroom | E1: Store Type | F1: Visited | G1: Visit Date | H1: Team Visited | I1: Remarks
A2: MEGA COLOMBO METRO ZONE | B2: MEGA COLOMBO METRO ZONE | C2: MEGA COLOMBO METRO ZONE- | D2: MEGA - SHANGRI-LA | E2: Mega | F2: No
A3: MEGA COLOMBO METRO ZONE | B3: MEGA COLOMBO METRO ZONE | C3: MEGA COLOMBO METRO ZONE- | D3: MEGA -COLPETTY | E3: Mega | F3: No
A4: MEGA COLOMBO METRO ZONE | B4: MEGA COLOMBO METRO ZONE | C4: MEGA COLOMBO METRO ZONE- | D4: MEGA -HAVELOCK CITY | E4: Mega | F4: No
A5: MEGA COLOMBO METRO ZONE | B5: MEGA COLOMBO METRO ZONE | C5: MEGA COLOMBO METRO ZONE- | D5: MEGA -THURSTAN ROAD | E5: Mega | F5: No
A6: MEGA COLOMBO METRO ZONE | B6: MEGA COLOMBO METRO ZONE | C6: MEGA COLOMBO METRO ZONE- | D6: MEGA -WAREHOUSE | E6: Warehouse | F6: No
A7: MEGA COLOMBO METRO ZONE | B7: MEGA COLOMBO METRO ZONE | C7: MEGA COLOMBO METRO ZONE- | D7: MEGA-MILAGIRIYA | E7: Mega | F7: No
A8: MEGA COLOMBO METRO ZONE | B8: MEGA COLOMBO METRO ZONE | C8: MEGA COLOMBO METRO ZONE- | D8: Samsung Smart Things | E8: Standard | F8: No
A9: MEGA NORTH ZONE | B9: MEGA NORTH ZONE | C9: MEGA NORTH ZONE- | D9: MEGA - PELIYAGODA | E9: Mega | F9: No
A10: MEGA NORTH ZONE | B10: MEGA NORTH ZONE | C10: MEGA NORTH ZONE- | D10: MEGA -JA-ELA | E10: Mega | F10: No
A11: MEGA NORTH ZONE | B11: MEGA NORTH ZONE | C11: MEGA NORTH ZONE- | D11: MEGA -KADUWELA | E11: Mega | F11: No
A12: MEGA NORTH ZONE | B12: MEGA NORTH ZONE | C12: MEGA NORTH ZONE- | D12: MEGA -KURUNAGALA | E12: Mega | F12: No
A13: MEGA NORTH ZONE | B13: MEGA NORTH ZONE | C13: MEGA NORTH ZONE- | D13: MEGA -MALABE | E13: Mega | F13: No
... A30: MEGA SOUTH ZONE | B30: MEGA SOUTH ZONE | C30: MEGA SOUTH ZONE- | D30: MEGA-MAHARAGAMA | E30: Mega | F30: No
A31: MEGA SOUTH ZONE | B31: MEGA SOUTH ZONE | C31: MEGA SOUTH ZONE- | D31: MEGA-MATARA | E31: Mega | F31: Yes | G31: 28.07.2026 | H31: Digital
A32: MEGA SOUTH ZONE | B32: MEGA SOUTH ZONE | C32: MEGA SOUTH ZONE- | D32: MEGA-MOUNT LAVINIA | E32: Mega | F32: No
A33: MEGA SOUTH ZONE | B33: MEGA SOUTH ZONE | C33: MEGA SOUTH ZONE- | D33: MEGA-NUGEGODA | E33: Mega | F33: No
A34: MEGA SOUTH ZONE | B34: MEGA SOUTH ZONE | C34: MEGA SOUTH ZONE- | D34: MEGA-RAJAGIRIYA | E34: Mega | F34: No
A35: MEGA SOUTH ZONE | B35: MEGA SOUTH ZONE | C35: MEGA SOUTH ZONE- | D35: SHOMES-RATHMALANA | E35: Singer Homes | F35: No
A36: NORTH REGION CENTRAL AREA | B36: NORTH REGION CENTRAL AREA | C36: DIGANA | D36: BUDGET SHOP-K-GTOTA | E36: Budget Shop | F36: No
A37: NORTH REGION CENTRAL AREA | B37: NORTH REGION CENTRAL AREA | C37: DIGANA | D37: DIGANA | E37: Standard | F37: No
A38: NORTH REGION CENTRAL AREA | B38: NORTH REGION CENTRAL AREA | C38: DIGANA | D38: DIGANA - B | E38: Standard | F38: No
A39: NORTH REGION CENTRAL AREA | B39: NORTH REGION CENTRAL AREA | C39: DIGANA | D39: GALAGEDARA | E39: Standard | F39: No
A40: NORTH REGION CENTRAL AREA | B40: NORTH REGION CENTRAL AREA | C40: DIGANA | D40: KATUGASTOTA | E40: Standard | F40: No
A41: NORTH REGION CENTRAL AREA | B41: NORTH REGION CENTRAL AREA | C41: DIGANA | D41: KATUGASTOTA - B | E41: Standard | F41: No
A42: NORTH REGION CENTRAL AREA | B42: NORTH REGION CENTRAL AREA | C42: DIGANA | D42: KUNDASALE | E42: Standard | F42: No
A43: NORTH REGION CENTRAL AREA | B43: NORTH REGION CENTRAL AREA | C43: DIGANA | D43: MENIKHINNA | E43: Standard | F43: No
... A153: NORTH REGION EAST AREA | B153: NORTH REGION EAST AREA | C153: POLONNARUWA | D153: WELIKANDA | E153: Standard | F153: No
A154: NORTH REGION NORTH AREA | B154: NORTH REGION NORTH AREA | C154: ANURADHAPURA | D154: ANURADHAPURA A | E154: Standard | F154: Yes | G154: 22.07.2026 | H154: Digital / K/ Appalince Team
A155: NORTH REGION NORTH AREA | B155: NORTH REGION NORTH AREA | C155: ANURADHAPURA | D155: ANURADHAPURA B | E155: Standard | F155: Yes | G155: 23.07.2026 | H155: Digital / K/ Appalince Team
A156: NORTH REGION NORTH AREA | B156: NORTH REGION NORTH AREA | C156: ANURADHAPURA | D156: ANURADHAPURA C | E156: Standard | F156: Yes | G156: 22.07.2026 | H156: K/ Appalince Team
A157: NORTH REGION NORTH AREA | B157: NORTH REGION NORTH AREA | C157: ANURADHAPURA | D157: EPPAWELA | E157: Standard | F157: No
A158: NORTH REGION NORTH AREA | B158: NORTH REGION NORTH AREA | C158: ANURADHAPURA | D158: GALGAMUWA | E158: Standard | F158: Yes | G158: 22.07.2026 | H158: Digital
A159: NORTH REGION NORTH AREA | B159: NORTH REGION NORTH AREA | C159: ANURADHAPURA | D159: GALNEWA | E159: Standard | F159: No
A160: NORTH REGION NORTH AREA | B160: NORTH REGION NORTH AREA | C160: ANURADHAPURA | D160: NOCHCHIYAGAMA | E160: Standard | F160: No
A161: NORTH REGION NORTH AREA | B161: NORTH REGION NORTH AREA | C161: ANURADHAPURA | D161: SHOMES- ANURADHAPURA | E161: Singer Homes | F161: Yes | G161: 23.07.2026 | H161: Digital / K/ Appalince Team
A162: NORTH REGION NORTH AREA | B162: NORTH REGION NORTH AREA | C162: ANURADHAPURA | D162: THALAWA | E162: Standard | F162: Yes | G162: 22.07.2026 | H162: Digital
A163: NORTH REGION NORTH AREA | B163: NORTH REGION NORTH AREA | C163: ANURADHAPURA | D163: THAMBUTTEGAMA | E163: Standard | F163: Yes | G163: 22.07.2026 | H163: Digital
A164: NORTH REGION NORTH AREA | B164: NORTH REGION NORTH AREA | C164: ANURADHAPURA | D164: WILACHCHIYA | E164: Standard | F164: No
A165: NORTH REGION NORTH AREA | B165: NORTH REGION NORTH AREA | C165: JAFFNA | D165: CHANKANI | E165: Standard | F165: No
...

Sheet Summary
A1: Category | B1: Value
A2: Total Showrooms | B2: =COUNTA('Visit Tracker'!D2:D1048576) -> 431
A3: Visited | B3: =COUNTIF('Visit Tracker'!F:F,"Yes") -> 37
A4: Pending | B4: =COUNTIF('Visit Tracker'!F:F,"No") -> 394
A5: % Complete | B5: =IF(B2=0,0,B3/B2) -> 0.085846868

Sheet District Summary
A1: District | B1: Total | C1: Visited | D1: Pending
A2: AKURESSA | B2: =COUNTIF('Visit Tracker'!C:C,A2) -> 9 | C2: =COUNTIFS('Visit Tracker'!C:C,A2,'Visit Tracker'!F:F,"Yes") -> 0 | D2: =B2-C2 -> 9
A3: AMBALANGODA | B3: =COUNTIF('Visit Tracker'!C:C,A3) -> 10 | C3: =COUNTIFS('Visit Tracker'!C:C,A3,'Visit Tracker'!F:F,"Yes") -> 0 | D3: =B3-C3 -> 10
A4: AMPARA | B4: =COUNTIF('Visit Tracker'!C:C,A4) -> 8 | C4: =COUNTIFS('Visit Tracker'!C:C,A4,'Visit Tracker'!F:F,"Yes") -> 0 | D4: =B4-C4 -> 8
A5: ANURADHAPURA | B5: =COUNTIF('Visit Tracker'!C:C,A5) -> 11 | C5: =COUNTIFS('Visit Tracker'!C:C,A5,'Visit Tracker'!F:F,"Yes") -> 7 | D5: =B5-C5 -> 4
A6: BADULLA | B6: =COUNTIF('Visit Tracker'!C:C,A6) -> 15 | C6: =COUNTIFS('Visit Tracker'!C:C,A6,'Visit Tracker'!F:F,"Yes") -> 0 | D6: =B6-C6 -> 15
A7: BAMBALAPITIYA | B7: =COUNTIF('Visit Tracker'!C:C,A7) -> 9 | C7: =COUNTIFS('Visit Tracker'!C:C,A7,'Visit Tracker'!F:F,"Yes") -> 0 | D7: =B7-C7 -> 9
A8: BATTICALOA | B8: =COUNTIF('Visit Tracker'!C:C,A8) -> 8 | C8: =COUNTIFS('Visit Tracker'!C:C,A8,'Visit Tracker'!F:F,"Yes") -> 0 | D8: =B8-C8 -> 8
A9: BORELLA | B9: =COUNTIF('Visit Tracker'!C:C,A9) -> 11 | C9: =COUNTIFS('Visit Tracker'!C:C,A9,'Visit Tracker'!F:F,"Yes") -> 0 | D9: =B9-C9 -> 11
A10: CHILAW | B10: =COUNTIF('Visit Tracker'!C:C,A10) -> 13 | C10: =COUNTIFS('Visit Tracker'!C:C,A10,'Visit Tracker'!F:F,"Yes") -> 0 | D10: =B10-C10 -> 13
A11: DAMBULLA | B11: =COUNTIF('Visit Tracker'!C:C,A11) -> 11 | C11: =COUNTIFS('Visit Tracker'!C:C,A11,'Visit Tracker'!F:F,"Yes") -> 0 | D11: =B11-C11 -> 11
A12: DIGANA | B12: =COUNTIF('Visit Tracker'!C:C,A12) -> 12 | C12: =COUNTIFS('Visit Tracker'!C:C,A12,'Visit Tracker'!F:F,"Yes") -> 0 | D12: =B12-C12 -> 12
A13: EMBILIPITIYA | B13: =COUNTIF('Visit Tracker'!C:C,A13) -> 14 | C13: =COUNTIFS('Visit Tracker'!C:C,A13,'Visit Tracker'!F:F,"Yes") -> 10 | D13: =B13-C13 -> 4
... A40: VAVUNIYA | B40: =COUNTIF('Visit Tracker'!C:C,A40) -> 10 | C40: =COUNTIFS('Visit Tracker'!C:C,A40,'Visit Tracker'!F:F,"Yes") -> 0 | D40: =B40-C40 -> 10

Sheet Area Summary
A1: Area | B1: Total | C1: Visited | D1: Pending
A2: MEGA COLOMBO METRO ZONE | B2: =COUNTIF('Visit Tracker'!B:B,A2) -> 7 | C2: =COUNTIFS('Visit Tracker'!B:B,A2,'Visit Tracker'!F:F,"Yes") -> 0 | D2: =B2-C2 -> 7
A3: MEGA NORTH ZONE | B3: =COUNTIF('Visit Tracker'!B:B,A3) -> 13 | C3: =COUNTIFS('Visit Tracker'!B:B,A3,'Visit Tracker'!F:F,"Yes") -> 0 | D3: =B3-C3 -> 13
A4: MEGA SOUTH ZONE | B4: =COUNTIF('Visit Tracker'!B:B,A4) -> 14 | C4: =COUNTIFS('Visit Tracker'!B:B,A4,'Visit Tracker'!F:F,"Yes") -> 1 | D4: =B4-C4 -> 13
A5: NORTH REGION CENTRAL AREA | B5: =COUNTIF('Visit Tracker'!B:B,A5) -> 36 | C5: =COUNTIFS('Visit Tracker'!B:B,A5,'Visit Tracker'!F:F,"Yes") -> 0 | D5: =B5-C5 -> 36
A6: NORTH REGION COLOMBO AREA NORTH | B6: =COUNTIF('Visit Tracker'!B:B,A6) -> 45 | C6: =COUNTIFS('Visit Tracker'!B:B,A6,'Visit Tracker'!F:F,"Yes") -> 0 | D6: =B6-C6 -> 45
A7: NORTH REGION EAST AREA | B7: =COUNTIF('Visit Tracker'!B:B,A7) -> 37 | C7: =COUNTIFS('Visit Tracker'!B:B,A7,'Visit Tracker'!F:F,"Yes") -> 0 | D7: =B7-C7 -> 37
A8: NORTH REGION NORTH AREA | B8: =COUNTIF('Visit Tracker'!B:B,A8) -> 41 | C8: =COUNTIFS('Visit Tracker'!B:B,A8,'Visit Tracker'!F:F,"Yes") -> 12 | D8: =B8-C8 -> 29
A9: NORTH REGION WAYAMBA AREA | B9: =COUNTIF('Visit Tracker'!B:B,A9) -> 47 | C9: =COUNTIFS('Visit Tracker'!B:B,A9,'Visit Tracker'!F:F,"Yes") -> 6 | D9: =B9-C9 -> 41
A10: SOUTH REGION COLOMBO AREA SOUTH | B10: =COUNTIF('Visit Tracker'!B:B,A10) -> 35 | C10: =COUNTIFS('Visit Tracker'!B:B,A10,'Visit Tracker'!F:F,"Yes") -> 4 | D10: =B10-C10 -> 31
A11: SOUTH REGION COLOMBO METRO AREA | B11: =COUNTIF('Visit Tracker'!B:B,A11) -> 43 | C11: =COUNTIFS('Visit Tracker'!B:B,A11,'Visit Tracker'!F:F,"Yes") -> 0 | D11: =B11-C11 -> 43
A12: SOUTH REGION SABARAGAMUWA AREA | B12: =COUNTIF('Visit Tracker'!B:B,A12) -> 38 | C12: =COUNTIFS('Visit Tracker'!B:B,A12,'Visit Tracker'!F:F,"Yes") -> 13 | D12: =B12-C12 -> 25
A13: SOUTH REGION SOUTH AREA | B13: =COUNTIF('Visit Tracker'!B:B,A13) -> 40 | C13: =COUNTIFS('Visit Tracker'!B:B,A13,'Visit Tracker'!F:F,"Yes") -> 1 | D13: =B13-C13 -> 39
A14: SOUTH REGION UVA AREA | B14: =COUNTIF('Visit Tracker'!B:B,A14) -> 35 | C14: =COUNTIFS('Visit Tracker'!B:B,A14,'Visit Tracker'!F:F,"Yes") -> 0 | D14: =B14-C14 -> 35
